<?xml version="1.0"?>
<robot xmlns:xacro="http://wiki.ros.org/xacro">



	
<xacro:macro name="robotiq_gripper" params="transmission_hw_interface gripper_active grasp_plugin">

	<!-- include  macros to be used--> 
	
	<xacro:include filename="$(find gripper_description)/urdf/robotiq/robotiq_85_gripper.transmission.xacro" />
	<xacro:property name="pi" value="3.14159"/>

	<xacro:macro name="mimic_joint_plugin_gazebo" params="name_prefix parent_joint mimic_joint has_pid:=false multiplier:=1.0 offset:=0 sensitiveness:=0.0 max_effort:=1.0 robot_namespace:=''">
		<gazebo>
			<plugin name="${name_prefix}mimic_joint_plugin" filename="libroboticsgroup_upatras_gazebo_mimic_joint_plugin.so">
				<joint>${parent_joint}</joint>
				<mimicJoint>${mimic_joint}</mimicJoint>
				<xacro:if value="${has_pid}">                     <!-- if set to true, PID parameters from "/gazebo_ros_control/pid_gains/${mimic_joint}" are loaded -->
					<hasPID />
				</xacro:if>
				<multiplier>${multiplier}</multiplier>
				<offset>${offset}</offset>
				<sensitiveness>${sensitiveness}</sensitiveness>   <!-- if absolute difference between setpoint and process value is below this threshold, do nothing; 0.0 = disable [rad] -->
				<maxEffort>${max_effort}</maxEffort>              <!-- only taken into account if has_pid:=true [Nm] -->
				<xacro:unless value="${robot_namespace == ''}">
					<robotNamespace>($robot_namespace)</robotNamespace>
				</xacro:unless>
			</plugin>
		</gazebo>
	</xacro:macro>




	  <link name="gripper_base">    
	    <visual>
	      <origin xyz="0.2275 0 0 " rpy="${-pi/2} 0 0"/>
	   	<geometry>
		    <mesh filename="package://gripper_description/meshes/gripper_base_up.stl" scale="0.001 0.001 0.001"/>
		</geometry>
	    </visual>
	    <collision>
	      <origin xyz="0.2275 0 0" rpy="${-pi/2} 0 0"/>
	    <geometry>
		    <mesh filename="package://gripper_description/meshes/gripper_base_up.stl" scale="0.001 0.001 0.001"/>
		</geometry>
	    </collision>
	  </link>

		
		
		<joint name="robotiq_85_base_joint" type="fixed">
			<parent link="gripper_base"/>
			<child link="robotiq_85_base_link"/>
			<origin rpy="0. -${pi/2} 0.0" xyz="0.0 0. 0.0"/>
		</joint>


	        <link name="robotiq_85_base_link">
			<visual>
				<geometry>
					<mesh filename="package://gripper_description/meshes/robotiq/visual/robotiq_85_base_link.dae"/>
				</geometry>
			</visual>
			<collision>
				<geometry>
					<mesh filename="package://gripper_description/meshes/robotiq/collision/robotiq_85_base_link.stl"/>
				</geometry>
			</collision>
			<inertial>
				<mass value="0.636951" />
				<origin xyz="0.0 0.0 0.0" />
				<inertia ixx = "0.000380" ixy = "0.000000" ixz = "0.000000"
					iyx = "0.000000" iyy = "0.001110" iyz = "0.000000"
					izx = "0.000000" izy = "0.000000" izz = "0.001171" />
			</inertial>
		</link>




	<xacro:unless value="${gripper_active}">
	   <joint name="hand_1_joint" type="fixed">
    	<parent link="robotiq_85_base_link"/>
   		 <child link="robotiq_85_left_knuckle_link"/>
    	 <origin rpy="${pi} 0.0 0.0" xyz="0.05490451627 0.03060114443 0.0"/>
	   </joint>
	</xacro:unless>
	<xacro:if value="${gripper_active}">
		<joint name="hand_1_joint" type="revolute">
			<parent link="robotiq_85_base_link"/>
			<child link="robotiq_85_left_knuckle_link"/>
			<axis xyz="0 0 1"/>
			<origin rpy="${pi} 0.0 0.0" xyz="0.05490451627 0.03060114443 0.0"/>
			<limit lower="0.0" upper="0.804" velocity="0.5" effort="50"/>
			<dynamics damping="100.0" />
		</joint>
	</xacro:if>




		<gazebo reference="robotiq_85_left_knuckle_link">
			<kp>1000000.0</kp>
			<kd>100.0</kd>
			<mu1>30.0</mu1>
			<mu2>30.0</mu2>
			<maxVel>1.0</maxVel>
			<minDepth>0.001</minDepth>
			<material>Gazebo/Grey</material>
		</gazebo>




		<xacro:unless value="${gripper_active}">
		   <joint name="robotiq_85_right_knuckle_joint" type="fixed">
			<parent link="robotiq_85_base_link"/>
	   		 <child link="robotiq_85_right_knuckle_link"/>
			 <origin rpy="0.0 0.0 0.0" xyz="0.05490451627 -0.03060114443 0.0"/>
		   </joint>
		</xacro:unless>
		<xacro:if value="${gripper_active}">
			<joint name="robotiq_85_right_knuckle_joint" type="continuous">
				<parent link="robotiq_85_base_link"/>
				<child link="robotiq_85_right_knuckle_link"/>
				<axis xyz="0 0 1"/>
				<origin rpy="0.0 0.0 0.0" xyz="0.05490451627 -0.03060114443 0.0"/>
				<limit lower="-3.14" upper="3.14" velocity="100.0" effort="50"/>
				<mimic joint="hand_1_joint"/>
				<dynamics damping="100.0" />
			</joint>
		</xacro:if>




		<gazebo reference="robotiq_85_right_knuckle_link">
			<kp>1000000.0</kp>
			<kd>100.0</kd>
			<mu1>30.0</mu1>
			<mu2>30.0</mu2>
			<maxVel>1.0</maxVel>
			<minDepth>0.001</minDepth>
			<material>Gazebo/Grey</material>
		</gazebo>
		<xacro:mimic_joint_plugin_gazebo name_prefix="{prefix}robotiq_85_right_knuckle_joint"
			parent_joint="hand_1_joint" mimic_joint="robotiq_85_right_knuckle_joint"
			multiplier="1.0" max_effort="10.0" />


		<link name="robotiq_85_left_knuckle_link">
			<visual>
				<geometry>
					<mesh filename="package://gripper_description/meshes/robotiq/visual/robotiq_85_knuckle_link.dae"/>
				</geometry>
			</visual>
			<collision>
				<geometry>
					<mesh filename="package://gripper_description/meshes/robotiq/collision/robotiq_85_knuckle_link.stl"/>
				</geometry>
			</collision>
			<inertial>
				<mass value="0.018491" />
				<origin xyz="0.0 0.0 0.0" />
				<inertia ixx = "0.000009" ixy = "-0.000001" ixz = "0.000000"
					iyx = "-0.000001" iyy = "0.000001" iyz = "0.000000"
					izx = "0.000000" izy = "0.000000" izz = "0.000010" />
			</inertial>
		</link>

		<link name="robotiq_85_right_knuckle_link">
			<visual>
				<geometry>
					<mesh filename="package://gripper_description/meshes/robotiq/visual/robotiq_85_knuckle_link.dae"/>
				</geometry>
			</visual>
			<collision>
				<geometry>
					<mesh filename="package://gripper_description/meshes/robotiq/collision/robotiq_85_knuckle_link.stl"/>
				</geometry>
			</collision>
			<inertial>
				<mass value="0.018491" />
				<origin xyz="0.0 0.0 0.0" />
				<inertia ixx = "0.000009" ixy = "-0.000001" ixz = "0.000000"
					iyx = "-0.000001" iyy = "0.000001" iyz = "0.000000"
					izx = "0.000000" izy = "0.000000" izz = "0.000010" />
			</inertial>
		</link>

		<joint name="robotiq_85_left_finger_joint" type="fixed">
			<parent link="robotiq_85_left_knuckle_link"/>
			<child link="robotiq_85_left_finger_link"/>
			<origin xyz="-0.00408552455 -0.03148604435 0.0" rpy="0 0 0" />
		</joint>


		<joint name="robotiq_85_right_finger_joint" type="fixed">
			<parent link="robotiq_85_right_knuckle_link"/>
			<child link="robotiq_85_right_finger_link"/>
			<origin xyz="-0.00408552455 -0.03148604435 0.0" rpy="0 0 0" />
		</joint>


		<link name="robotiq_85_left_finger_link">
			<visual>
				<geometry>
					<mesh filename="package://gripper_description/meshes/robotiq/visual/robotiq_85_finger_link.dae"/>
				</geometry>
			</visual>
			<collision>
				<geometry>
					<mesh filename="package://gripper_description/meshes/robotiq/collision/robotiq_85_finger_link.stl"/>
				</geometry>
			</collision>
			<inertial>
				<mass value="0.027309" />
				<origin xyz="0.0 0.0 0.0" />
				<inertia ixx = "0.000003" ixy = "-0.000002" ixz = "0.000000"
					iyx = "-0.000002" iyy = "0.000021" iyz = "0.000000"
					izx = "0.000000" izy = "0.000000" izz = "0.000020" />
			</inertial>
		</link>


		<link name="robotiq_85_right_finger_link">
			<visual>
				<geometry>
					<mesh filename="package://gripper_description/meshes/robotiq/visual/robotiq_85_finger_link.dae"/>
				</geometry>
			</visual>
			<collision>
				<geometry>
					<mesh filename="package://gripper_description/meshes/robotiq/collision/robotiq_85_finger_link.stl"/>
				</geometry>
			</collision>
			<inertial>
				<mass value="0.027309" />
				<origin xyz="0.0 0.0 0.0" />
				<inertia ixx = "0.000003" ixy = "-0.000002" ixz = "0.000000"
					iyx = "-0.000002" iyy = "0.000021" iyz = "0.000000"
					izx = "0.000000" izy = "0.000000" izz = "0.000020" />
			</inertial>
		</link>


		<xacro:unless value="${gripper_active}">
		   <joint name="robotiq_85_left_inner_knuckle_joint" type="fixed">
			<parent link="robotiq_85_base_link"/>
	   		 <child link="robotiq_85_left_inner_knuckle_link"/>
			<origin xyz="0.06142 0.0127 0" rpy="${pi} 0.0 0.0" />
		   </joint>
		</xacro:unless>
		<xacro:if value="${gripper_active}">
		<joint name="robotiq_85_left_inner_knuckle_joint" type="continuous">
			<parent link="robotiq_85_base_link"/>
			<child link="robotiq_85_left_inner_knuckle_link"/>
			<axis xyz="0 0 1"/>
			<origin xyz="0.06142 0.0127 0" rpy="${pi} 0.0 0.0" />
			<limit lower="-3.14" upper="3.14" velocity="100.0" effort="0.1"/>
			<mimic joint="hand_1_joint" offset="0"/>
		</joint>
		</xacro:if>



		<xacro:mimic_joint_plugin_gazebo name_prefix="robotiq_85_left_inner_knuckle_joint"
			parent_joint="hand_1_joint" mimic_joint="robotiq_85_left_inner_knuckle_joint"
			multiplier="1.0" max_effort="10.0" />
			
			
		
		<xacro:unless value="${gripper_active}">
		   <joint name="robotiq_85_right_inner_knuckle_joint" type="fixed">
			<parent link="robotiq_85_base_link"/>
	   		 <child link="robotiq_85_right_inner_knuckle_link"/>
			<origin xyz="0.06142 -0.0127 0" rpy="0 0 0"/>
		   </joint>
		</xacro:unless>
		<xacro:if value="${gripper_active}">
		<joint name="robotiq_85_right_inner_knuckle_joint" type="continuous">
			<parent link="robotiq_85_base_link"/>
			<child link="robotiq_85_right_inner_knuckle_link"/>
			<axis xyz="0 0 1"/>
			<origin xyz="0.06142 -0.0127 0" rpy="0 0 0"/>
			<limit lower="-3.14" upper="3.14" velocity="100.0" effort="0.1"/>
			<mimic joint="hand_1_joint" offset="0"/>
		</joint>
		</xacro:if>
	


		<xacro:mimic_joint_plugin_gazebo name_prefix="robotiq_85_right_inner_knuckle_joint"
			parent_joint="hand_1_joint" mimic_joint="robotiq_85_right_inner_knuckle_joint"
			multiplier="1.0" max_effort="10.0" />

		<link name="robotiq_85_left_inner_knuckle_link">
			<visual>
				<geometry>
					<mesh filename="package://gripper_description/meshes/robotiq/visual/robotiq_85_inner_knuckle_link.dae"/>
				</geometry>
			</visual>
			<collision>
				<geometry>
					<mesh filename="package://gripper_description/meshes/robotiq/collision/robotiq_85_inner_knuckle_link.stl"/>
				</geometry>
			</collision>
			<inertial>
				<mass value="0.029951" />
				<origin xyz="0.0 0.0 0.0" />
				<inertia ixx = "0.000039" ixy = "0.000000" ixz = "0.000000"
					iyx = "0.000000" iyy = "0.000005" iyz = "0.000000"
					izx = "0.000000" izy = "0.000000" izz = "0.000035" />
			</inertial>
		</link>
		<link name="robotiq_85_right_inner_knuckle_link">
			<visual>
				<geometry>
					<mesh filename="package://gripper_description/meshes/robotiq/visual/robotiq_85_inner_knuckle_link.dae"/>
				</geometry>
			</visual>
			<collision>
				<geometry>
					<mesh filename="package://gripper_description/meshes/robotiq/collision/robotiq_85_inner_knuckle_link.stl"/>
				</geometry>
			</collision>
			<inertial>
				<mass value="0.029951" />
				<origin xyz="0.0 0.0 0.0" />
				<inertia ixx = "0.000039" ixy = "0.000000" ixz = "0.000000"
					iyx = "0.000000" iyy = "0.000005" iyz = "0.000000"
					izx = "0.000000" izy = "0.000000" izz = "0.000035" />
			</inertial>
		</link>

		
		<xacro:unless value="${gripper_active}">
		   <joint name="robotiq_85_left_finger_tip_joint" type="fixed">
			<parent link="robotiq_85_left_inner_knuckle_link"/>
	   		 <child link="robotiq_85_left_finger_tip_link"/>
			<origin xyz="0.04303959807 -0.03759940821 0.0" rpy="0.0 0.0 0.0"/>
			</joint>
		</xacro:unless>
		<xacro:if value="${gripper_active}">
			<joint name="robotiq_85_left_finger_tip_joint" type="continuous">
				<parent link="robotiq_85_left_inner_knuckle_link"/>
				<child link="robotiq_85_left_finger_tip_link"/>
				<axis xyz="0 0 1"/>
				<origin xyz="0.04303959807 -0.03759940821 0.0" rpy="0.0 0.0 0.0"/>
				<limit lower="-3.14" upper="3.14" velocity="100.0" effort="0.1"/>
				<mimic joint="hand_1_joint" multiplier="-1"/>
			</joint>
		</xacro:if>




		<xacro:mimic_joint_plugin_gazebo name_prefix="robotiq_85_left_finger_tip_joint"
			parent_joint="hand_1_joint" mimic_joint="robotiq_85_left_finger_tip_joint"
			multiplier="1.0" max_effort="10.0" />
			
			
				
		<xacro:unless value="${gripper_active}">
		   <joint name="robotiq_85_right_finger_tip_joint" type="fixed">
			<parent link="robotiq_85_right_inner_knuckle_link"/>
	   		 <child link="robotiq_85_right_finger_tip_link"/>
				<origin rpy="0.0 0.0 0.0" xyz="0.04303959807 -0.03759940821  0.0"/>
			</joint>
		</xacro:unless>
		<xacro:if value="${gripper_active}">
		<joint name="robotiq_85_right_finger_tip_joint" type="continuous">
			<parent link="robotiq_85_right_inner_knuckle_link"/>
			<child link="robotiq_85_right_finger_tip_link"/>
			<axis xyz="0 0 1"/>
			<origin rpy="0.0 0.0 0.0" xyz="0.04303959807 -0.03759940821  0.0"/>
			<limit lower="-3.14" upper="3.14" velocity="100.0" effort="0.1"/>
			<mimic joint="hand_1_joint" multiplier="-1"/>
		</joint>
		</xacro:if>
	


		<xacro:mimic_joint_plugin_gazebo name_prefix="robotiq_85_right_finger_tip_joint"
			parent_joint="hand_1_joint" mimic_joint="robotiq_85_right_finger_tip_joint"
			multiplier="1.0" max_effort="10.0" />

		<link name="robotiq_85_left_finger_tip_link">
			<visual>
				<geometry>
					<mesh filename="package://gripper_description/meshes/robotiq/visual/robotiq_85_finger_tip_link.dae"/>
				</geometry>
			</visual>
			<collision>
				<geometry>
					<mesh filename="package://gripper_description/meshes/robotiq/collision/robotiq_85_finger_tip_link.stl"/>
				</geometry>
			</collision>
			<inertial>
				<mass value="0.019555" />
				<origin xyz="0.0 0.0 0.0" />
				<inertia ixx = "0.000002" ixy = "0.000000" ixz = "0.000000"
					iyx = "0.000000" iyy = "0.000005" iyz = "0.000000"
					izx = "0.000000" izy = "0.000000" izz = "0.000006" />
			</inertial>
		</link>

		<gazebo reference="robotiq_85_left_finger_tip_link">
			<kp>1000000.0</kp>
			<kd>100.0</kd>
			<mu1>30.0</mu1>
			<mu2>30.0</mu2>
			<maxVel>1.0</maxVel>
			<minDepth>0.001</minDepth>
			<material>Gazebo/Grey</material>
		</gazebo>
		<link name="robotiq_85_right_finger_tip_link">
			<visual>
				<geometry>
					<mesh filename="package://gripper_description/meshes/robotiq/visual/robotiq_85_finger_tip_link.dae"/>
				</geometry>
			</visual>
			<collision>
				<geometry>
					<mesh filename="package://gripper_description/meshes/robotiq/collision/robotiq_85_finger_tip_link.stl"/>
				</geometry>
			</collision>
			<inertial>
				<mass value="0.019555" />
				<origin xyz="0.0 0.0 0.0" />
				<inertia ixx = "0.000002" ixy = "0.000000" ixz = "0.000000"
					iyx = "0.000000" iyy = "0.000005" iyz = "0.000000"
					izx = "0.000000" izy = "0.000000" izz = "0.000006" />
			</inertial>
		</link>

		<gazebo reference="robotiq_85_right_finger_tip_link">
			<kp>1000000.0</kp>
			<kd>100.0</kd>
			<mu1>30.0</mu1>
			<mu2>30.0</mu2>
			<maxVel>1.0</maxVel>
			<minDepth>0.001</minDepth>
			<material>Gazebo/Grey</material>
		</gazebo>
		<xacro:robotiq_85_gripper_transmission  prefix="" transmission_hw_interface="${transmission_hw_interface}" />




	<joint name="fixed_ee_gripper" type="fixed">
			<origin xyz="0 0 0.12" rpy="0 0 0"/>
			<parent link="gripper_base"/>
			<child  link="tool0"/>
	</joint>
	<link name="tool0"/>




	<!-- the plugin for grasping that creates a dynamic link with the object when grasping forces are sent is described here:-->
	<!-- https://github-wiki-see.page/m/JenniferBuehler/gazebo-pkgs/wiki/The-Gazebo-grasp-fix-plugin-->
	<xacro:if value="${grasp_plugin}">
		<gazebo>
		   <plugin name="gazebo_grasp_fix" filename="libgazebo_grasp_fix.so">
			<arm>
			   <arm_name>ur5</arm_name>
			   <palm_link> wrist_3_link  </palm_link>
			   <gripper_link> robotiq_85_left_finger_link </gripper_link>
			   <gripper_link> robotiq_85_right_finger_link </gripper_link>
			</arm>
		       <forces_angle_tolerance>100</forces_angle_tolerance>
		       <update_rate>500</update_rate>
		       <grip_count_threshold>4</grip_count_threshold>
		       <max_grip_count>20</max_grip_count>
		       <release_tolerance>0.01</release_tolerance>
		       <disable_collisions_on_attach>true</disable_collisions_on_attach>
		       <contact_topic>__default_topic__</contact_topic>
		    </plugin>
		</gazebo>

	</xacro:if>

  </xacro:macro>
</robot>

